<robot
  name="revel">
  <link
    name="base_link">
    <inertial>
      <origin
        xyz="-0.0023730528889142 -0.00502093782805647 0.0237603120106106"
        rpy="0 0 0" />
      <mass
        value="0.774961748747901" />
    <inertia
        ixx="0.00201866828203214"
        ixy="-1.40341741820078E-05"
        ixz="5.0229742322277E-06"
        iyy="0.00196560351814595"
        iyz="2.49903357518308E-05"
        izz="0.00317820785242523" />
    </inertial>

    <visual>
      <origin
        xyz="0 0 0"
        rpy="0 0 0" />
      <geometry>
        <mesh
          filename="package://4_25_urdf6/meshes/base_link.STL" />
      </geometry>
      <material
        name="">
        <color
          rgba="0.792156862745098 0.819607843137255 0.933333333333333 1" />
      </material>
    </visual>
    <collision>
      <origin
        xyz="0 0 0"
        rpy="0 0 0" />
      <geometry>
        <mesh
          filename="package://4_25_urdf6/meshes/base_link.STL" />
      </geometry>
    </collision>
  </link>

  <link
    name="link_1">
    <inertial>
      <origin
        xyz="-1.5879447236338E-05 -0.00709916492149038 0.0638496557944277"
        rpy="0 0 0" />
      <mass
        value="0.29849024" />
      <inertia
        ixx="0.000632049493639531"
        ixy="4.97008463061611E-09"
        ixz="-3.22891235511891E-07"
        iyy="0.000568859462204089"
        iyz="5.38876127197549E-05"
        izz="0.000140153748296134" />
    </inertial>
    <visual>
      <origin
        xyz="0 0 0"
        rpy="0 0 0" />
      <geometry>
        <mesh
          filename="package://4_25_urdf6/meshes/link_1.STL" />
      </geometry>
      <material
        name="">
        <color
          rgba="0.898039215686275 0.917647058823529 0.929411764705882 1" />
      </material>
    </visual>
    <collision>
      <origin
        xyz="0 0 0"
        rpy="0 0 0" />
      <geometry>
        <mesh
          filename="package://4_25_urdf6/meshes/link_1.STL" />
      </geometry>
    </collision>
  </link>
  <joint
    name="joint_1"
    type="revolute">
    <origin
      xyz="0 0 0.06485"
      rpy="0 0 -1.5708" />
    <parent
      link="base_link" />
    <child
      link="link_1" />
    <axis
      xyz="0 0 1" />
    <limit
      lower="-3.14"
      upper="3.14"
      effort="30"
      velocity="1.0" />
  </joint>

  <transmission name="tran1">
    <type>transmission_interface/SimpleTransmission</type>
    <joint name="joint_1">
      <hardwareInterface>EffortJointInterface</hardwareInterface>
    </joint>
  <actuator name="foo_motor">
    <mechanicalReduction>50</mechanicalReduction>
    <hardwareInterface>EffortJointInterface</hardwareInterface>
  </actuator>
  </transmission>

</robot>
