<robot
  name="revel">
  <link
    name="base_link">
    <inertial>
      <origin
        xyz="-0.0023730528889142 -0.00502093782805647 0.0237603120106106"
        rpy="0 0 0" />
      <mass
        value="0.438546009395726" />
      <inertia
        ixx="0.00101057713013944"
        ixy="-1.3327151795118E-05"
        ixz="3.8013573363164E-07"
        iyy="0.000959740758547222"
        iyz="1.36174962948068E-05"
        izz="0.00151576833373158" />
    </inertial>
    <visual>
      <origin
        xyz="0 0 0"
        rpy="0 0 0" />
      <geometry>
        <mesh
          filename="package://4_25_urdf6/meshes/base_link.STL" />
      </geometry>
      <material
        name="">
        <color
          rgba="0.792156862745098 0.819607843137255 0.933333333333333 1" />
      </material>
    </visual>
    <collision>
      <origin
        xyz="0 0 0"
        rpy="0 0 0" />
      <geometry>
        <mesh
          filename="package://4_25_urdf6/meshes/base_link.STL" />
      </geometry>
    </collision>
  </link>
  <link
    name="link_1">
    <inertial>
      <origin
        xyz="-1.5879447236338E-05 -0.00709916492149038 0.0638496557944277"
        rpy="0 0 0" />
      <mass
        value="0.21227632351697" />
      <inertia
        ixx="0.000390294391971273"
        ixy="-1.99057422257391E-08"
        ixz="-1.30802993677179E-07"
        iyy="0.000349377287881694"
        iyz="3.96416720459436E-05"
        izz="9.38628502767779E-05" />
    </inertial>
    <visual>
      <origin
        xyz="0 0 0"
        rpy="0 0 0" />
      <geometry>
        <mesh
          filename="package://4_25_urdf6/meshes/link_1.STL" />
      </geometry>
      <material
        name="">
        <color
          rgba="0.898039215686275 0.917647058823529 0.929411764705882 1" />
      </material>
    </visual>
    <collision>
      <origin
        xyz="0 0 0"
        rpy="0 0 0" />
      <geometry>
        <mesh
          filename="package://4_25_urdf6/meshes/link_1.STL" />
      </geometry>
    </collision>
  </link>
  <joint
    name="joint_1"
    type="revolute">
    <origin
      xyz="0 0 0.06485"
      rpy="0 0 -1.5708" />
    <parent
      link="base_link" />
    <child
      link="link_1" />
    <axis
      xyz="0 0 -1" />
    <limit
      lower="0"
      upper="6.0"
      effort="30"
      velocity="1.0" />
  </joint>
  <link
    name="link_2">
    <inertial>
      <origin
        xyz="9.60103803698233E-07 0.107533810370169 0.00620995831245331"
        rpy="0 0 0" />
      <mass
        value="0.293474008383791" />
      <inertia
        ixx="0.00225022357114847"
        ixy="-9.60850883967213E-09"
        ixz="-4.43844579851517E-09"
        iyy="0.000140576264450523"
        iyz="0.00018997435572042"
        izz="0.00220368381821717" />
    </inertial>
    <visual>
      <origin
        xyz="0 0 0"
        rpy="0 0 0" />
      <geometry>
        <mesh
          filename="package://4_25_urdf6/meshes/link_2.STL" />
      </geometry>
      <material
        name="">
        <color
          rgba="0.898039215686275 0.917647058823529 0.929411764705882 1" />
      </material>
    </visual>
    <collision>
      <origin
        xyz="0 0 0"
        rpy="0 0 0" />
      <geometry>
        <mesh
          filename="package://4_25_urdf6/meshes/link_2.STL" />
      </geometry>
    </collision>
  </link>
  <joint
    name="joint_2"
    type="revolute">
    <origin
      xyz="0 -0.015113 0.1155"
      rpy="1.5708 0 4.3282E-16" />
    <parent
      link="link_1" />
    <child
      link="link_2" />
    <axis
      xyz="0 0 -1" />
    <limit
      lower="-2"
      upper="2"
      effort="30"
      velocity="1.0" />
  </joint>
  <link
    name="link_3">
    <inertial>
      <origin
        xyz="-0.00271183900274356 0.0610091301092551 0.00559400264418311"
        rpy="0 0 0" />
      <mass
        value="0.254948895895984" />
      <inertia
        ixx="0.000754190414215377"
        ixy="3.05338561010444E-05"
        ixz="-4.1313097699641E-06"
        iyy="0.00013661856463044"
        iyz="9.30634602239697E-05"
        izz="0.000773028116455631" />
    </inertial>
    <visual>
      <origin
        xyz="0 0 0"
        rpy="0 0 0" />
      <geometry>
        <mesh
          filename="package://4_25_urdf6/meshes/link_3.STL" />
      </geometry>
      <material
        name="">
        <color
          rgba="0.898039215686275 0.917647058823529 0.929411764705882 1" />
      </material>
    </visual>
    <collision>
      <origin
        xyz="0 0 0"
        rpy="0 0 0" />
      <geometry>
        <mesh
          filename="package://4_25_urdf6/meshes/link_3.STL" />
      </geometry>
    </collision>
  </link>
  <joint
    name="joint_3"
    type="revolute">
    <origin
      xyz="0 0.2277 -0.009226"
      rpy="3.1416 -1.5345E-16 3.1416" />
    <parent
      link="link_2" />
    <child
      link="link_3" />
    <axis
      xyz="0 0 -1" />
    <limit
      lower="-2"
      upper="2"
      effort="30"
      velocity="1.0" />
  </joint>
  <link
    name="link_4">
    <inertial>
      <origin
        xyz="0.00313257969328566 0.0815755631836339 -0.00624759833233165"
        rpy="0 0 0" />
      <mass
        value="0.220706391128874" />
      <inertia
        ixx="0.000694656697810584"
        ixy="-2.50951587549425E-05"
        ixz="-3.21737084342497E-06"
        iyy="0.000159457919129819"
        iyz="-8.39232726027445E-05"
        izz="0.00064764384602654" />
    </inertial>
    <visual>
      <origin
        xyz="0 0 0"
        rpy="0 0 0" />
      <geometry>
        <mesh
          filename="package://4_25_urdf6/meshes/link_4.STL" />
      </geometry>
      <material
        name="">
        <color
          rgba="0.898039215686275 0.917647058823529 0.929411764705882 1" />
      </material>
    </visual>
    <collision>
      <origin
        xyz="0 0 0"
        rpy="0 0 0" />
      <geometry>
        <mesh
          filename="package://4_25_urdf6/meshes/link_4.STL" />
      </geometry>
    </collision>
  </link>
  <joint
    name="joint_4"
    type="revolute">
    <origin
      xyz="-0.00165 0.1377 -0.000388"
      rpy="0 1.5708 0" />
    <parent
      link="link_3" />
    <child
      link="link_4" />
    <axis
      xyz="0 0 1" />
    <limit
      lower="-1.7"
      upper="1.7"
      effort="30"
      velocity="1.0" />
  </joint>
  <link
    name="link_5">
    <inertial>
      <origin
        xyz="0.000198872480250657 0.0318752691244907 0.00773763240050632"
        rpy="0 0 0" />
      <mass
        value="0.163854288137822" />
      <inertia
        ixx="0.000177331781147381"
        ixy="1.29308489343752E-07"
        ixz="1.97866268691943E-07"
        iyy="0.000129668345614458"
        iyz="3.29586592910205E-05"
        izz="0.000140389798299154" />
    </inertial>
    <visual>
      <origin
        xyz="0 0 0"
        rpy="0 0 0" />
      <geometry>
        <mesh
          filename="package://4_25_urdf6/meshes/link_5.STL" />
      </geometry>
      <material
        name="">
        <color
          rgba="0.898039215686275 0.917647058823529 0.929411764705882 1" />
      </material>
    </visual>
    <collision>
      <origin
        xyz="0 0 0"
        rpy="0 0 0" />
      <geometry>
        <mesh
          filename="package://4_25_urdf6/meshes/link_5.STL" />
      </geometry>
    </collision>
  </link>
  <joint
    name="joint_5"
    type="revolute">
    <origin
      xyz="0.00165 0.1504 -0.0015875"
      rpy="0 1.5708 0" />
    <parent
      link="link_4" />
    <child
      link="link_5" />
    <axis
      xyz="0 0 -1" />
    <limit
      lower="-1.7"
      upper="1.7"
      effort="30"
      velocity="1.0" />
  </joint>
  <link
    name="link_6">
    <inertial>
      <origin
        xyz="0.00579554535449743 -1.99117701069566E-05 -0.0330401015812523"
        rpy="0 0 0" />
      <mass
        value="0.210564848441307" />
      <inertia
        ixx="0.000137363872234681"
        ixy="-3.20648763983526E-06"
        ixz="-1.17271419616097E-05"
        iyy="0.000276011790395281"
        iyz="5.78816301512628E-09"
        izz="0.000246179867065394" />
    </inertial>
    <visual>
      <origin
        xyz="0 0 0"
        rpy="0 0 0" />
      <geometry>
        <mesh
          filename="package://4_25_urdf6/meshes/link_6.STL" />
      </geometry>
      <material
        name="">
        <color
          rgba="0.792156862745098 0.819607843137255 0.933333333333333 1" />
      </material>
    </visual>
    <collision>
      <origin
        xyz="0 0 0"
        rpy="0 0 0" />
      <geometry>
        <mesh
          filename="package://4_25_urdf6/meshes/link_6.STL" />
      </geometry>
    </collision>
  </link>
  <joint
    name="joint_6"
    type="revolute">
    <origin
      xyz="-0.01475 0.08 0.001425"
      rpy="1.5708 3.14159 0" />
    <parent
      link="link_5" />
    <child
      link="link_6" />
    <axis
      xyz="0 0 -1" />
    <limit
      lower="0"
      upper="6.0"
      effort="30"
      velocity="1.0" />
  </joint>
  <link
    name="link_7">
    <inertial>
      <origin
        xyz="-4.33014013534461E-10 4.1616174568937E-10 0.022087275711041"
        rpy="0 0 0" />
      <mass
        value="0.0177292628019284" />
      <inertia
        ixx="9.82169789482217E-06"
        ixy="2.58836323876685E-06"
        ixz="-2.12436204405245E-20"
        iyy="8.58698982788479E-06"
        iyz="1.49410346492048E-20"
        izz="1.04158739441426E-05" />
    </inertial>
    <visual>
      <origin
        xyz="0 0 0"
        rpy="0 0 0" />
      <geometry>
        <mesh
          filename="package://4_25_urdf6/meshes/link_finger_1.STL" />
      </geometry>
      <material
        name="">
        <color
          rgba="0.752941176470588 0.752941176470588 0.752941176470588 1" />
      </material>
    </visual>
    <collision>
      <origin
        xyz="0 0 0"
        rpy="0 0 0" />
      <geometry>
        <mesh
          filename="package://4_25_urdf6/meshes/link_finger_1.STL" />
      </geometry>
    </collision>
  </link>
  <joint
    name="joint_7"
    type="prismatic">
    <origin
      xyz="0 0 -0.052509"
      rpy="3.1416 3.0358E-17 3.1416" />
    <parent
      link="link_6" />
    <child
      link="link_7" />
    <axis
      xyz="-1 0 0" />
    <limit
      lower="-0.05"
      upper="0.05"
      effort="30"
      velocity="1.0" />
  </joint>
</robot>
