<robot name="revel">
   
   <gazebo>
     <plugin name="gazebo_ros_control" filename="libgazebo_ros_control.so">
       <robotNamespace>/revel/</robotNamespace>
     </plugin>
   </gazebo>

  <link name="world"/>

  <link
    name="base_link">
    <inertial>
      <origin
        xyz="0.00172138710918983 -0.00127182285419577 0.0171989779561854"
        rpy="0 0 0" />
      <mass
        value="0.789077111415677" />
      <inertia
        ixx="0.00180919549981355"
        ixy="3.96127678509164E-05"
        ixz="3.72331115957062E-06"
        iyy="0.00186100428609199"
        iyz="5.1715770693461E-06"
        izz="0.00296777279990657" />
    </inertial>
    <visual>
      <origin
        xyz="0 0 0"
        rpy="0 0 0" />
      <geometry>
        <mesh
          filename="package://svenzva_description/meshes/base_link.STL" />
      </geometry>
      <material
        name="">
        <color
          rgba="0.898039215686275 0.917647058823529 0.929411764705882 1" />
      </material>
    </visual>
    <collision>
      <origin
        xyz="0 0 0"
        rpy="0 0 0" />
      <geometry>
        <mesh
          filename="package://svenzva_description/meshes/base_link.STL" />
      </geometry>
    </collision>
  </link>
  
  <joint name="world_joint" type="fixed">
    <parent link="world"/>
    <child link="base_link"/>
  </joint>

  <link
    name="link_1">
    <inertial>
      <origin
        xyz="0.000382323924907779 -0.00470237960817645 0.048986864070067"
        rpy="0 0 0" />
      <mass
        value="0.285081724446302" />
      <inertia
        ixx="0.000576265153577692"
        ixy="-7.29667721561119E-08"
        ixz="-8.77576458279432E-09"
        iyy="0.000529836048035276"
        iyz="5.77007799659921E-05"
        izz="0.000148508459691431" />
    </inertial>
    <visual>
      <origin
        xyz="0 0 0"
        rpy="0 0 0" />
      <geometry>
        <mesh
          filename="package://svenzva_description/meshes/link_1.STL" />
      </geometry>
      <material
        name="">
        <color
          rgba="0.529411764705882 0.549019607843137 0.549019607843137 1" />
      </material>
    </visual>
    <collision>
      <origin
        xyz="0 0 0"
        rpy="0 0 0" />
      <geometry>
        <mesh
          filename="package://svenzva_description/meshes/link_1.STL" />
      </geometry>
    </collision>
  </link>
  <joint
    name="joint_1"
    type="revolute">
    <origin
      xyz="0 0 0.064752"
      rpy="0 0 0" />
    <parent
      link="base_link" />
    <child
      link="link_1" />
    <axis
      xyz="0 0 -1" />
    <limit
      lower="-3.14"
      upper="3.14"
      effort="10"
      velocity="1" />
  </joint>
  <link
    name="link_2">
    <inertial>
      <origin
        xyz="6.68273573298239E-07 0.0986387198382099 0.0169547740706888"
        rpy="0 0 0" />
      <mass
        value="0.500798339631218" />
      <inertia
        ixx="0.0036367297891374"
        ixy="-1.25836059204981E-08"
        ixz="-2.71479092518923E-09"
        iyy="0.000278127522594296"
        iyz="0.000219169974604029"
        izz="0.00354509300980195" />
    </inertial>
    <visual>
      <origin
        xyz="0 0 0"
        rpy="0 0 0" />
      <geometry>
        <mesh
          filename="package://svenzva_description/meshes/link_2.STL" />
      </geometry>
      <material
        name="">
        <color
          rgba="0.898039215686275 0.917647058823529 0.929411764705882 1" />
      </material>
    </visual>
    <collision>
      <origin
        xyz="0 0 0"
        rpy="0 0 0" />
      <geometry>
        <mesh
          filename="package://svenzva_description/meshes/link_2.STL" />
      </geometry>
    </collision>
  </link>
  <joint
    name="joint_2"
    type="revolute">
    <origin
      xyz="0.00038333 -0.0069353 0.10441"
      rpy="1.5708 0 0" />
    <parent
      link="link_1" />
    <child
      link="link_2" />
    <axis
      xyz="0 0 -1" />
    <limit
      lower="-2.2"
      upper="2.2"
      effort="10"
      velocity="1" />
  </joint>
  <link
    name="link_3">
    <inertial>
      <origin
        xyz="2.06877629402302E-07 0.0892255662413822 -0.0104327032850908"
        rpy="0 0 0" />
      <mass
        value="0.371611749675941" />
      <inertia
        ixx="0.00199013272502536"
        ixy="8.78637741788359E-09"
        ixz="1.39431229709039E-08"
        iyy="0.000274495763261598"
        iyz="-0.000142409809065274"
        izz="0.00183970414671987" />
    </inertial>
    <visual>
      <origin
        xyz="0 0 0"
        rpy="0 0 0" />
      <geometry>
        <mesh
          filename="package://svenzva_description/meshes/link_3.STL" />
      </geometry>
      <material
        name="">
        <color
          rgba="0.898039215686275 0.917647058823529 0.929411764705882 1" />
      </material>
    </visual>
    <collision>
      <origin
        xyz="0 0 0"
        rpy="0 0 0" />
      <geometry>
        <mesh
          filename="package://svenzva_description/meshes/link_3.STL" />
      </geometry>
    </collision>
  </link>
  <joint
    name="joint_3"
    type="revolute">
    <origin
      xyz="0 0.2224 0.014294"
      rpy="0 0 0" />
    <parent
      link="link_2" />
    <child
      link="link_3" />
    <axis
      xyz="0 0 1" />
    <limit
      lower="-2.2"
      upper="2.2"
      effort="10"
      velocity="1" />
  </joint>
  <link
    name="link_4">
    <inertial>
      <origin
        xyz="-4.62874663839097E-05 0.0460237856790803 0.0041785313367854"
        rpy="0 0 0" />
      <mass
        value="0.186398780121232" />
      <inertia
        ixx="0.000224502830743652"
        ixy="-3.47243279411846E-07"
        ixz="-3.72183402123759E-08"
        iyy="7.66738741171304E-05"
        iyz="-1.37078235584345E-05"
        izz="0.000188070378573453" />
    </inertial>
    <visual>
      <origin
        xyz="0 0 0"
        rpy="0 0 0" />
      <geometry>
        <mesh
          filename="package://svenzva_description/meshes/link_4.STL" />
      </geometry>
      <material
        name="">
        <color
          rgba="0.898039215686275 0.917647058823529 0.929411764705882 1" />
      </material>
    </visual>
    <collision>
      <origin
        xyz="0 0 0"
        rpy="0 0 0" />
      <geometry>
        <mesh
          filename="package://svenzva_description/meshes/link_4.STL" />
      </geometry>
    </collision>
  </link>
  <joint
    name="joint_4"
    type="revolute">
    <origin
      xyz="0 0.19605 -0.015019"
      rpy="0 0 0" />
    <parent
      link="link_3" />
    <child
      link="link_4" />
    <axis
      xyz="0 -1 0" />
    <limit
      lower="-2.5"
      upper="4.0"
      effort="10"
      velocity="1" />
  </joint>
  <link
    name="link_5">
    <inertial>
      <origin
        xyz="2.84174077891386E-06 -0.00977369262826872 0.0338026247899146"
        rpy="0 0 0" />
      <mass
        value="0.141592490303688" />
      <inertia
        ixx="0.000165281635565983"
        ixy="-1.03408539253725E-08"
        ixz="-5.17732962077127E-09"
        iyy="0.000112913458998206"
        iyz="-2.66459907852557E-05"
        izz="8.63145645924559E-05" />
    </inertial>
    <visual>
      <origin
        xyz="0 0 0"
        rpy="0 0 0" />
      <geometry>
        <mesh
          filename="package://svenzva_description/meshes/link_5.STL" />
      </geometry>
      <material
        name="">
        <color
          rgba="0.898039215686275 0.917647058823529 0.929411764705882 1" />
      </material>
    </visual>
    <collision>
      <origin
        xyz="0 0 0"
        rpy="0 0 0" />
      <geometry>
        <mesh
          filename="package://svenzva_description/meshes/link_5.STL" />
      </geometry>
    </collision>
  </link>
  <joint
    name="joint_5"
    type="revolute">
    <origin
      xyz="0 0.08375 0.0040438"
      rpy="-1.5708 0 0" />
    <parent
      link="link_4" />
    <child
      link="link_5" />
    <axis
      xyz="0 1 0" />
    <limit
      lower="-1.7"
      upper="1.7"
      effort="10"
      velocity="1" />
  </joint>
  <link
    name="link_6">
    <inertial>
      <origin
        xyz="-0.00471982494214871 1.67002418636347E-05 -0.0315774325152575"
        rpy="0 0 0" />
      <mass
        value="0.222489248107418" />
      <inertia
        ixx="0.000143192829312104"
        ixy="-4.0175973317761E-06"
        ixz="1.05236950727609E-05"
        iyy="0.000281202041909366"
        iyz="1.4956238261439E-08"
        izz="0.000244858478472157" />
    </inertial>
    <visual>
      <origin
        xyz="0 0 0"
        rpy="0 0 0" />
      <geometry>
        <mesh
          filename="package://svenzva_description/meshes/link_6.STL" />
      </geometry>
      <material
        name="">
        <color
          rgba="0.898039215686275 0.917647058823529 0.929411764705882 1" />
      </material>
    </visual>
    <collision>
      <origin
        xyz="0 0 0"
        rpy="0 0 0" />
      <geometry>
        <mesh
          filename="package://svenzva_description/meshes/link_6.STL" />
      </geometry>
    </collision>
  </link>
  <joint
    name="joint_6"
    type="revolute">
    <origin
      xyz="0 -0.019119 0.082"
      rpy="3.1416 0 1.5708" />
    <parent
      link="link_5" />
    <child
      link="link_6" />
    <axis
      xyz="0 0 -1" />
    <limit
      lower="0.5"
      upper="5.5"
      effort="10"
      velocity="1" />
  </joint>
 <link
    name="finger_link_1">
    <inertial>
      <origin
        xyz="-0.00483282204262809 -0.00411403012500923 0.0206210772714723"
        rpy="0 0 1.5708" />
      <mass
        value="0.0220307791071739" />
      <inertia
        ixx="9.08331950596468E-06"
        ixy="-2.05394082888464E-06"
        ixz="-2.23772944669454E-06"
        iyy="1.04239718244321E-05"
        iyz="-2.75990314800171E-06"
        izz="9.60841591398502E-06" />
    </inertial>
    <visual>
      <origin
        xyz="0 0 0"
        rpy="0 0 1.5708" />
      <geometry>
        <mesh
          filename="package://svenzva_description/meshes/finger_link_1.STL" />
      </geometry>
      <material
        name="">
        <color
          rgba="0.898039215686275 0.917647058823529 0.929411764705882 1" />
      </material>
    </visual>
    <collision>
      <origin
        xyz="0 0 0"
        rpy="0 0 0" />
      <geometry>
        <mesh
          filename="package://svenzva_description/meshes/finger_link_1.STL" />
      </geometry>
    </collision>
  </link>

  <joint
    name="finger_joint_1"
    type="prismatic">
    <origin
      xyz="0 0 -0.052509"
      rpy="-3.1416 -1.8964E-18 3.1416" />
    <parent
      link="link_6" />
    <child
      link="finger_link_1" />
    <axis
      xyz="-1 0 0" />
    <limit
      lower="0"
      upper="0.05"
      effort="100"
      velocity="10" />
  </joint>

 <link
    name="finger_joint_2">
    <inertial>
      <origin
        xyz="0.00483282233149502 0.00411402197005728 0.020621076918268"
        rpy="0 0 1.5708" />
      <mass
        value="0.0220307791071739" />
      <inertia
        ixx="9.08331950596466E-06"
        ixy="-2.05394082888463E-06"
        ixz="2.23772944669453E-06"
        iyy="1.04239718244321E-05"
        iyz="2.75990314800169E-06"
        izz="9.60841591398501E-06" />
    </inertial>
    <visual>
      <origin
        xyz="0 0 0"
        rpy="0 0 1.5708" />
      <geometry>
        <mesh
          filename="package://svenzva_description/meshes/finger_joint_2.STL" />
      </geometry>
      <material
        name="">
        <color
          rgba="0.898039215686275 0.917647058823529 0.929411764705882 1" />
      </material>
    </visual>
    <collision>
      <origin
        xyz="0 0 0"
        rpy="0 0 0" />
      <geometry>
        <mesh
          filename="package://svenzva_description/meshes/finger_joint_2.STL" />
      </geometry>
    </collision>
  </link>
  <joint
    name="finger_joint_2"
    type="prismatic">
    <origin
      xyz="0 0 -0.052509"
      rpy="-3.1416 -1.8964E-18 3.1416" />
    <parent
      link="link_6" />
    <child
      link="finger_joint_2" />
    <axis
      xyz="-1 0 0" />
    <limit
      lower="-0.05"
      upper="0"
      effort="100"
      velocity="10" />
  </joint>

  <link name="ee_link"> </link>
  <joint name="ee_joint" type="fixed">
    <parent link="link_6"/>
    <child link="ee_link"/>
    <origin xyz="0 0 -0.05" rpy="3.14159 0 0"/>
  </joint>

  <transmission name="joint_1_trans">
    <type>transmission_interface/SimpleTransmission</type>
    <joint name="joint_1">
      <hardwareInterface>EffortJointInterface</hardwareInterface>
    </joint>
    <actuator name="motor_1">
      <mechanicalReduction>4</mechanicalReduction>
      <hardwareInterface>EffortJointInterface</hardwareInterface>
    </actuator>
  </transmission>

  <transmission name="joint_2_trans">
    <type>transmission_interface/SimpleTransmission</type>
    <joint name="joint_2">
      <hardwareInterface>EffortJointInterface</hardwareInterface>
    </joint>
  <actuator name="motor_2">
    <mechanicalReduction>6</mechanicalReduction>
    <hardwareInterface>EffortJointInterface</hardwareInterface>
  </actuator>
  </transmission>

  <transmission name="joint_3_trans">
    <type>transmission_interface/SimpleTransmission</type>
    <joint name="joint_3">
      <hardwareInterface>EffortJointInterface</hardwareInterface>
    </joint>
  <actuator name="motor_3">
    <mechanicalReduction>6</mechanicalReduction>
    <hardwareInterface>EffortJointInterface</hardwareInterface>
  </actuator>
  </transmission>

  <transmission name="joint_4_trans">
    <type>transmission_interface/SimpleTransmission</type>
    <joint name="joint_4">
      <hardwareInterface>EffortJointInterface</hardwareInterface>
    </joint>
  <actuator name="motor_4">
    <mechanicalReduction>1</mechanicalReduction>
    <hardwareInterface>EffortJointInterface</hardwareInterface>
  </actuator>
  </transmission>

  <transmission name="joint_5_trans">
    <type>transmission_interface/SimpleTransmission</type>
    <joint name="joint_5">
      <hardwareInterface>EffortJointInterface</hardwareInterface>
    </joint>
  <actuator name="motor_5">
    <mechanicalReduction>4</mechanicalReduction>
    <hardwareInterface>EffortJointInterface</hardwareInterface>
  </actuator>
  </transmission>

 <transmission name="joint_6_trans">
    <type>transmission_interface/SimpleTransmission</type>
    <joint name="joint_6">
      <hardwareInterface>EffortJointInterface</hardwareInterface>
    </joint>
    <actuator name="motor_6">
    <mechanicalReduction>1</mechanicalReduction>
    <hardwareInterface>EffortJointInterface</hardwareInterface>
     </actuator>
  </transmission>



</robot>
