<robot
  name="revel">
  <link
    name="base_link">
    <inertial>
      <origin
        xyz="0.0 0.0 0.02376"
        rpy="0 0 0" />
      <mass
        value="0.6323" />
    <inertia
        ixx="0.000481"
        ixy="-1E-06"
        ixz="0"
        iyy="0.000439"
        iyz="-1.2E-05"
        izz="0.000112" />
    </inertial>

    <visual>
      <origin
        xyz="0 0 0"
        rpy="0 0 0" />
      <geometry>
        <mesh
          filename="package://svenzva_description/meshes/base_link.STL" />
      </geometry>
      <material
        name="">
        <color
          rgba="0.792156862745098 0.819607843137255 0.933333333333333 1" />
      </material>
    </visual>
    <collision>
      <origin
        xyz="0 0 0"
        rpy="0 0 0" />
      <geometry>
        <mesh
          filename="package://svenzva_description/meshes/base_link.STL" />
      </geometry>
    </collision>
  </link>
  <link
    name="link_1">
    <inertial>
      <origin
        xyz="0 -0.007 0.0638"
        rpy="0 0 0" />
      <mass
        value="0.300074" />
      <inertia
        ixx="0.000481"
        ixy="-1.0E-06"
        ixz="0"
        iyy="0.000439"
        iyz="-1.2E-05"
        izz="0.000112" />
    </inertial>
    <visual>
      <origin
        xyz="0 0 0"
        rpy="0 0 0" />
      <geometry>
        <mesh
          filename="package://svenzva_description/meshes/link_1.STL" />
      </geometry>
      <material
        name="">
        <color
          rgba="0.898039215686275 0.917647058823529 0.929411764705882 1" />
      </material>
    </visual>
    <collision>
      <origin
        xyz="0 0 0"
        rpy="0 0 0" />
      <geometry>
        <mesh
          filename="package://svenzva_description/meshes/link_1.STL" />
      </geometry>
    </collision>
  </link>
  <joint
    name="joint_1"
    type="revolute">
    <origin
      xyz="0 0 0.06485"
      rpy="0 0 -1.5708" />
    <parent
      link="base_link" />
    <child
      link="link_1" />
    <axis
      xyz="0 0 -1" />
    <limit
      lower="-3.14"
      upper="3.14"
      effort="30"
      velocity="1.0" />
  </joint>
  <link
    name="link_2">
    <inertial>
      <origin
        xyz="0 0.10753 0.0"
        rpy="0 0 0" />
      <mass
        value="0.38526" />
      <inertia
        ixx="0.001575"
        ixy="0"
        ixz="-6.2E-05"
        iyy="0.012812"
        iyz="-3.0E-06"
        izz="0.000228" />
    </inertial>
    <visual>
      <origin
        xyz="0 0 0"
        rpy="0 0 0" />
      <geometry>
        <mesh
          filename="package://svenzva_description/meshes/link_2.STL" />
      </geometry>
      <material
        name="">
        <color
          rgba="0.898039215686275 0.917647058823529 0.929411764705882 1" />
      </material>
    </visual>
    <collision>
      <origin
        xyz="0 0 0"
        rpy="0 0 0" />
      <geometry>
        <mesh
          filename="package://svenzva_description/meshes/link_2.STL" />
      </geometry>
    </collision>
  </link>
  <joint
    name="joint_2"
    type="revolute">
    <origin
      xyz="0 0 0.1155"
      rpy="1.5708 0 0" />
    <parent
      link="link_1" />
    <child
      link="link_2" />
    <axis
      xyz="0 0 -1" />
    <limit
      lower="-2"
      upper="2"
      effort="30"
      velocity="1.0" />
  </joint>
  <link
    name="link_3">
    <inertial>
      <origin
        xyz="0.0 0.06100 0.0"
        rpy="0 0 0" />
      <mass
        value="0.312507" />
      <inertia
        ixx="0.000562"
        ixy="0"
        ixz="-5.0E-06"
        iyy="0.000493"
        iyz="-5.4E-05"
        izz="0.000175" />
    </inertial>
    <visual>
      <origin
        xyz="0 0 0"
        rpy="0 0 0" />
      <geometry>
        <mesh
          filename="package://svenzva_description/meshes/link_3.STL" />
      </geometry>
      <material
        name="">
        <color
          rgba="0.898039215686275 0.917647058823529 0.929411764705882 1" />
      </material>
    </visual>
    <collision>
      <origin
        xyz="0 0 0"
        rpy="0 0 0" />
      <geometry>
        <mesh
          filename="package://svenzva_description/meshes/link_3.STL" />
      </geometry>
    </collision>
  </link>
  <joint
    name="joint_3"
    type="revolute">
    <origin
      xyz="0 0.2277 0"
      rpy="3.1416 0.0 3.1416" />
    <parent
      link="link_2" />
    <child
      link="link_3" />
    <axis
      xyz="0 0 -1" />
    <limit
      lower="-2.2"
      upper="2.2"
      effort="30"
      velocity="1.0" />
  </joint>
  <link
    name="link_4">
    <inertial>
      <origin
        xyz="0.0 0.0815 0.0"
        rpy="0 0 0" />
      <mass
        value="0.295819" />
      <inertia
        ixx="0.00058148"
        ixy="3.1E-07"
        ixz="-3.842E-05"
        iyy="0.000059396"
        iyz="6.55E-06"
        izz="0.00018824" />

    </inertial>
    <visual>
      <origin
        xyz="0 0 0"
        rpy="0 0 0" />
      <geometry>
        <mesh
          filename="package://svenzva_description/meshes/link_4.STL" />
      </geometry>
      <material
        name="">
        <color
          rgba="0.898039215686275 0.917647058823529 0.929411764705882 1" />
      </material>
    </visual>
    <collision>
      <origin
        xyz="0 0 0"
        rpy="0 0 0" />
      <geometry>
        <mesh
          filename="package://svenzva_description/meshes/link_4.STL" />
      </geometry>
    </collision>
  </link>
  <joint
    name="joint_4"
    type="revolute">
    <origin
      xyz="0 0.1377 0"
      rpy="0 1.5708 0" />
    <parent
      link="link_3" />
    <child
      link="link_4" />
    <axis
      xyz="0 0 1" />
    <limit
      lower="-2.0"
      upper="2.0"
      effort="30"
      velocity="1.0" />
  </joint>
  <link
    name="link_5">
    <inertial>
      <origin
        xyz="0.0 0.03187 0.0"
        rpy="0 0 0" />
      <mass
        value="0.1901733" />
      <inertia
        ixx="0.000012768"
        ixy="-7.5E-07"
        ixz="-3.29E006"
        iyy="0.00013103"
        iyz="8.75E-06"
        izz="0.0001199" />
    </inertial>
    <visual>
      <origin
        xyz="0 0 0"
        rpy="0 0 0" />
      <geometry>
        <mesh
          filename="package://svenzva_description/meshes/link_5.STL" />
      </geometry>
      <material
        name="">
        <color
          rgba="0.898039215686275 0.917647058823529 0.929411764705882 1" />
      </material>
    </visual>
    <collision>
      <origin
        xyz="0 0 0"
        rpy="0 0 0" />
      <geometry>
        <mesh
          filename="package://svenzva_description/meshes/link_5.STL" />
      </geometry>
    </collision>
  </link>
  <joint
    name="joint_5"
    type="revolute">
    <origin
      xyz="0.0 0.1504 0.0"
      rpy="0 1.5708 0" />
    <parent
      link="link_4" />
    <child
      link="link_5" />
    <axis
      xyz="0 0 -1" />
    <limit
      lower="-1.7"
      upper="1.7"
      effort="30"
      velocity="1.0" />
  </joint>
  <link
    name="link_6">
    <inertial>
      <origin
        xyz="0.0 0.0 0.0"
        rpy="3.14159 0 0"/>
      <mass
        value="0.3029304" />
       <inertia
        ixx="0.00075338"
        ixy="-1.231E-05"
        ixz="3.7E-07"
        iyy="0.00022516"
        iyz="2.305E-05"
        izz="0.00066515" /> 
    </inertial>
    <visual>
      <origin
        xyz="0 0 0"
        rpy="3.14159 0 0" />
      <geometry>
        <mesh
          filename="package://svenzva_description/meshes/link_6.STL" />
      </geometry>
      <material
        name="">
        <color
          rgba="0.792156862745098 0.819607843137255 0.933333333333333 1" />
      </material>
    </visual>
    <collision>
      <origin
        xyz="0 0 0"
        rpy="1.5708 0 0" />
      <geometry>
        <mesh
          filename="package://svenzva_description/meshes/link_6.STL" />
      </geometry>
    </collision>
  </link>
  <joint
    name="joint_6"
    type="continuous">
    <origin
      xyz="0 0.08 0"
      rpy="-1.5807 0 0" />
    <parent
      link="link_5" />
    <child
      link="link_6" />
    <axis
      xyz="0 0 1" />
    <limit
      effort="100"
      velocity="100.0" />
  </joint>

  <!--
  <link
    name="link_7">
    <inertial>
      <origin
        xyz="0 0 0.022087275711041"
        rpy="0 0 0" />
      <mass
        value="0.0478690095652066" />
       <inertia
        ixx="2.65185843160199E-05"
        ixy="6.98858074467049E-06"
        ixz="-4.32758524413134E-20"
        iyy="2.31848725352889E-05"
        iyz="2.45012774391977E-20"
        izz="2.8122859649185E-05" />
    </inertial>  
    <visual>
      <origin
        xyz="0 0 0"
        rpy="0 0 0" />
      <geometry>
        <mesh
          filename="package://svenzva_description/meshes/link_finger_1.STL" />
      </geometry>
      <material
        name="">
        <color
          rgba="0.752941176470588 0.752941176470588 0.752941176470588 1" />
      </material>
    </visual>
    <collision>
      <origin
        xyz="0 0 0"
        rpy="0 0 0" />
      <geometry>
        <mesh
          filename="package://svenzva_description/meshes/link_finger_1.STL" />
      </geometry>
    </collision>
  </link>
  <joint
    name="joint_7"
    type="fixed">
    <origin
      xyz="0 0 -0.052509"
      rpy="3.1416 0 3.1416" />
    <parent
      link="link_6" />
    <child
      link="link_7" />
    <axis
      xyz="-1 0 0" />
    <limit
      lower="-0.05"
      upper="0.05"
      effort="30"
      velocity="1.0" />
  </joint>
-->
  <link name="ee_link"> </link>
  <joint name="ee_joint" type="fixed">
    <parent link="link_6"/>
    <child link="ee_link"/>
    <origin xyz="0.0 0 0.08" rpy="0 0 0"/>
  </joint>

</robot>
