<robot
  name="svenzva_armsvenzva_arm name="base_link">
    <inertial>
      <origin
        xyz="-0.00133562616624824 -0.00299591002016462 0.0153449295508581"
        rpy="0 0 0" />
      <mass
        value="0.722020764728074" />
      <inertia
        ixx="0.00192032665135544"
        ixy="-1.38171436818506E-05"
        ixz="7.88915046947883E-06"
        iyy="0.00186797485168719"
        iyz="3.14817845967135E-05"
        izz="0.00316707992917207" />
    </inertial>
    <visual>
      <origin
        xyz="0 0 0"
        rpy="0 0 0" />
      <geometry>
        <mesh
          filename="package://svenzva_description/meshes/base_link.STL" />
      </geometry>
      <material
        name="">
        <color
          rgba="0.898039215686275 0.917647058823529 0.929411764705882 1" />
      </material>
    </visual>
    <collision>
      <origin
        xyz="0 0 0"
        rpy="0 0 0" />
      <geometry>
        <mesh
          filename="package://svenzva_description/meshes/base_link.STL" />
      </geometry>
    </collision>
  </link>
  <link
    name="link_1">
    <inertial>
      <origin
        xyz="-0.00528149564542819 2.92409530103649E-05 0.0481308455186285"
        rpy="0 0 0" />
      <mass
        value="0.295038974095265" />
      <inertia
        ixx="0.000602988556413194"
        ixy="1.76219719457942E-09"
        ixz="5.74288697506272E-05"
        iyy="0.000654953956407552"
        iyz="2.88195997194193E-07"
        izz="0.000153905341508729" />
    </inertial>
    <visual>
      <origin
        xyz="0 0 0"
        rpy="0 0 0" />
      <geometry>
        <mesh
          filename="package://svenzva_description/meshes/link_1.STL" />
      </geometry>
      <material
        name="">
        <color
          rgba="0.898039215686275 0.917647058823529 0.929411764705882 1" />
      </material>
    </visual>
    <collision>
      <origin
        xyz="0 0 0"
        rpy="0 0 0" />
      <geometry>
        <mesh
          filename="package://svenzva_description/meshes/link_1.STL" />
      </geometry>
    </collision>
  </link>
  <joint
    name="joint_1"
    type="revolute">
    <origin
      xyz="0 0 0.0762"
      rpy="0 0 0" />
    <parent
      link="base_link" />
    <child
      link="link_1" />
    <axis
      xyz="0 0 -1" />
    <limit
      lower="-3.14"
      upper="3.14"
      effort="0"
      velocity="0" />
  </joint>
  <link
    name="link_2">
    <inertial>
      <origin
        xyz="8.17940782230075E-07 0.125408839850757 0.0120693662786398"
        rpy="0 0 0" />
      <mass
        value="0.350557648873674" />
      <inertia
        ixx="0.00290049583666862"
        ixy="-4.66260243339681E-09"
        ixz="-1.74520760929758E-09"
        iyy="0.000201563465404586"
        iyz="0.000261870918148287"
        izz="0.00282768721300917" />
    </inertial>
    <visual>
      <origin
        xyz="0 0 0"
        rpy="0 0 0" />
      <geometry>
        <mesh
          filename="package://svenzva_description/meshes/link_2.STL" />
      </geometry>
      <material
        name="">
        <color
          rgba="0.898039215686275 0.917647058823529 0.929411764705882 1" />
      </material>
    </visual>
    <collision>
      <origin
        xyz="0 0 0"
        rpy="0 0 0" />
      <geometry>
        <mesh
          filename="package://svenzva_description/meshes/link_2.STL" />
      </geometry>
    </collision>
  </link>
  <joint
    name="joint_2"
    type="revolute">
    <origin
      xyz="-0.007325 0 0.10542"
      rpy="1.5708 0 -1.5708" />
    <parent
      link="link_1" />
    <child
      link="link_2" />
    <axis
      xyz="0 0 -1" />
    <limit
      lower="-2"
      upper="2"
      effort="0"
      velocity="0" />
  </joint>
  <link
    name="link_3">
    <inertial>
      <origin
        xyz="-0.00224918997054324 0.0725742731372729 0.0140957004144005"
        rpy="0 0 0" />
      <mass
        value="0.227860881806706" />
      <inertia
        ixx="0.00112944348732024"
        ixy="4.15135248257336E-05"
        ixz="-3.43714764817888E-06"
        iyy="0.000132119085750405"
        iyz="0.00011068088305105"
        izz="0.00111351748824821" />
    </inertial>
    <visual>
      <origin
        xyz="0 0 0"
        rpy="0 0 0" />
      <geometry>
        <mesh
          filename="package://svenzva_description/meshes/link_3.STL" />
      </geometry>
      <material
        name="">
        <color
          rgba="0.898039215686275 0.917647058823529 0.929411764705882 1" />
      </material>
    </visual>
    <collision>
      <origin
        xyz="0 0 0"
        rpy="0 0 0" />
      <geometry>
        <mesh
          filename="package://svenzva_description/meshes/link_3.STL" />
      </geometry>
    </collision>
  </link>
  <joint
    name="joint_3"
    type="revolute">
    <origin
      xyz="0 0.2277 0.00635"
      rpy="3.1416 0 3.1416" />
    <parent
      link="link_2" />
    <child
      link="link_3" />
    <axis
      xyz="0 0 -1" />
    <limit
      lower="-2"
      upper="2"
      effort="0"
      velocity="0" />
  </joint>
  <link
    name="link_4">
    <inertial>
      <origin
        xyz="4.94200978125581E-05 0.00446272782448867 0.0502025183837943"
        rpy="0 0 0" />
      <mass
        value="0.174540765744632" />
      <inertia
        ixx="0.000200602142120969"
        ixy="3.98188281865171E-08"
        ixz="4.22246640456736E-07"
        iyy="0.000143330609528363"
        iyz="-7.54320528518119E-06"
        izz="9.50323421662128E-05" />
    </inertial>
    <visual>
      <origin
        xyz="0 0 0"
        rpy="0 0 0" />
      <geometry>
        <mesh
          filename="package://svenzva_description/meshes/link_4.STL" />
      </geometry>
      <material
        name="">
        <color
          rgba="0.898039215686275 0.917647058823529 0.929411764705882 1" />
      </material>
    </visual>
    <collision>
      <origin
        xyz="0 0 0"
        rpy="0 0 0" />
      <geometry>
        <mesh
          filename="package://svenzva_description/meshes/link_4.STL" />
      </geometry>
    </collision>
  </link>
  <joint
    name="joint_4"
    type="revolute">
    <origin
      xyz="-0.022225 0.17977 0.0074"
      rpy="1.5708 0 -3.1416" />
    <parent
      link="link_3" />
    <child
      link="link_4" />
    <axis
      xyz="0 0 1" />
    <limit
      lower="-5"
      upper="3.867"
      effort="0"
      velocity="0" />
  </joint>
  <link
    name="link_5">
    <inertial>
      <origin
        xyz="0.000241023608886559 0.0392574508036669 0.00184531476783182"
        rpy="0 0 0" />
      <mass
        value="0.133021865517638" />
      <inertia
        ixx="0.000108599166071625"
        ixy="3.76551051091788E-07"
        ixz="5.63803866067119E-09"
        iyy="9.94865517767143E-05"
        iyz="2.18016588858829E-06"
        izz="9.08075415393567E-05" />
    </inertial>
    <visual>
      <origin
        xyz="0 0 0"
        rpy="0 0 0" />
      <geometry>
        <mesh
          filename="package://svenzva_description/meshes/link_5.STL" />
      </geometry>
      <material
        name="">
        <color
          rgba="0.898039215686275 0.917647058823529 0.929411764705882 1" />
      </material>
    </visual>
    <collision>
      <origin
        xyz="0 0 0"
        rpy="0 0 0" />
      <geometry>
        <mesh
          filename="package://svenzva_description/meshes/link_5.STL" />
      </geometry>
    </collision>
  </link>
  <joint
    name="joint_5"
    type="revolute">
    <origin
      xyz="0 0.00165 0.07925"
      rpy="1.5708 0 -3.1416" />
    <parent
      link="link_4" />
    <child
      link="link_5" />
    <axis
      xyz="0 0 -1" />
    <limit
      lower="-1.7"
      upper="1.7"
      effort="0"
      velocity="0" />
  </joint>
  <link
    name="link_6">
    <inertial>
      <origin
        xyz="-0.00459904693334756 2.57945888126887E-05 -0.0327482586471116"
        rpy="0 0 0" />
      <mass
        value="0.243320868551208" />
      <inertia
        ixx="0.00016020334766947"
        ixy="-3.96748456837556E-06"
        ixz="1.08510273443082E-05"
        iyy="0.000326394043482595"
        iyz="1.11931196964281E-08"
        izz="0.000294334543327469" />
    </inertial>
    <visual>
      <origin
        xyz="0 0 0"
        rpy="0 0 0" />
      <geometry>
        <mesh
          filename="package://svenzva_description/meshes/link_6.STL" />
      </geometry>
      <material
        name="">
        <color
          rgba="0.250980392156863 0.250980392156863 0.250980392156863 1" />
      </material>
    </visual>
    <collision>
      <origin
        xyz="0 0 0"
        rpy="0 0 0" />
      <geometry>
        <mesh
          filename="package://svenzva_description/meshes/link_6.STL" />
      </geometry>
    </collision>
  </link>
  <joint
    name="joint_6"
    type="revolute">
    <origin
      xyz="-0.01475 0.08 0.001425"
      rpy="1.5708 0 0" />
    <parent
      link="link_5" />
    <child
      link="link_6" />
    <axis
      xyz="0 0 -1" />
    <limit
      lower="-1.565"
      upper="1.565"
      effort="0"
      velocity="0" />
  </joint>
</robot>
